Traceback (most recent call last):
  File "/Users/huangsir/opt/anaconda3/lib/python3.7/site-packages/gunicorn/arbiter.py", line 209, in run


During handling of the above exception, another exception occurred:

Traceback (most recent call last):
  File "/Users/huangsir/opt/anaconda3/bin/gunicorn", line 8, in <module>
    sys.exit(run())
  File "/Users/huangsir/opt/anaconda3/lib/python3.7/site-packages/gunicorn/app/wsgiapp.py", line 58, in run
    WSGIApplication("%(prog)s [OPTIONS] [APP_MODULE]").run()
  File "/Users/huangsir/opt/anaconda3/lib/python3.7/site-packages/gunicorn/app/base.py", line 228, in run
    super().run()
  File "/Users/huangsir/opt/anaconda3/lib/python3.7/site-packages/gunicorn/app/base.py", line 72, in run
    Arbiter(self).run()
  File "/Users/huangsir/opt/anaconda3/lib/python3.7/site-packages/gunicorn/arbiter.py", line 229, in run
    self.halt(reason=inst.reason, exit_status=inst.exit_status)
  File "/Users/huangsir/opt/anaconda3/lib/python3.7/site-packages/gunicorn/arbiter.py", line 342, in halt
    self.stop()
  File "/Users/huangsir/opt/anaconda3/lib/python3.7/site-packages/gunicorn/arbiter.py", line 393, in stop
    time.sleep(0.1)
  File "/Users/huangsir/opt/anaconda3/lib/python3.7/site-packages/gunicorn/arbiter.py", line 242, in handle_chld
    self.reap_workers()
  File "/Users/huangsir/opt/anaconda3/lib/python3.7/site-packages/gunicorn/arbiter.py", line 525, in reap_workers
    raise HaltServer(reason, self.WORKER_BOOT_ERROR)
gunicorn.errors.HaltServer: <HaltServer 'Worker failed to boot.' 3>
